2021-04-20 22:54:06,804 ERROR: Exception on /submit_contact [POST] [in /hdd/code/eastbournecottage/venv/lib/python3.8/site-packages/flask/app.py:1891]
Traceback (most recent call last):
  File "/hdd/code/eastbournecottage/venv/lib/python3.8/site-packages/flask/app.py", line 2447, in wsgi_app
    response = self.full_dispatch_request()
  File "/hdd/code/eastbournecottage/venv/lib/python3.8/site-packages/flask/app.py", line 1952, in full_dispatch_request
    rv = self.handle_user_exception(e)
  File "/hdd/code/eastbournecottage/venv/lib/python3.8/site-packages/flask/app.py", line 1821, in handle_user_exception
    reraise(exc_type, exc_value, tb)
  File "/hdd/code/eastbournecottage/venv/lib/python3.8/site-packages/flask/_compat.py", line 39, in reraise
    raise value
  File "/hdd/code/eastbournecottage/venv/lib/python3.8/site-packages/flask/app.py", line 1950, in full_dispatch_request
    rv = self.dispatch_request()
  File "/hdd/code/eastbournecottage/venv/lib/python3.8/site-packages/flask/app.py", line 1936, in dispatch_request
    return self.view_functions[rule.endpoint](**req.view_args)
  File "/hdd/code/eastbournecottage/app/routes.py", line 1003, in submit_contact
    msg = mail.Message('Contact Form: ' + contact_request['firstName'] + ' ' + contact_request['lastName'], sender=app.config['MAIL_USERNAME'], recipients=app.config['MAIL_USERNAME'])
TypeError: 'NoneType' object is not callable
