2021-04-12 17:03:58,478 ERROR: Exception on /admin [GET] [in /hdd/code/eastbournecottage/venv/lib/python3.8/site-packages/flask/app.py:1891]
Traceback (most recent call last):
  File "/hdd/code/eastbournecottage/venv/lib/python3.8/site-packages/flask/app.py", line 2447, in wsgi_app
    response = self.full_dispatch_request()
  File "/hdd/code/eastbournecottage/venv/lib/python3.8/site-packages/flask/app.py", line 1952, in full_dispatch_request
    rv = self.handle_user_exception(e)
  File "/hdd/code/eastbournecottage/venv/lib/python3.8/site-packages/flask/app.py", line 1821, in handle_user_exception
    reraise(exc_type, exc_value, tb)
  File "/hdd/code/eastbournecottage/venv/lib/python3.8/site-packages/flask/_compat.py", line 39, in reraise
    raise value
  File "/hdd/code/eastbournecottage/venv/lib/python3.8/site-packages/flask/app.py", line 1950, in full_dispatch_request
    rv = self.dispatch_request()
  File "/hdd/code/eastbournecottage/venv/lib/python3.8/site-packages/flask/app.py", line 1936, in dispatch_request
    return self.view_functions[rule.endpoint](**req.view_args)
  File "/hdd/code/eastbournecottage/venv/lib/python3.8/site-packages/flask_login/utils.py", line 270, in decorated_view
    elif not current_user.is_authenticated:
  File "/hdd/code/eastbournecottage/venv/lib/python3.8/site-packages/werkzeug/local.py", line 347, in __getattr__
    return getattr(self._get_current_object(), name)
  File "/hdd/code/eastbournecottage/venv/lib/python3.8/site-packages/werkzeug/local.py", line 306, in _get_current_object
    return self.__local()
  File "/hdd/code/eastbournecottage/venv/lib/python3.8/site-packages/flask_login/utils.py", line 26, in <lambda>
    current_user = LocalProxy(lambda: _get_user())
  File "/hdd/code/eastbournecottage/venv/lib/python3.8/site-packages/flask_login/utils.py", line 346, in _get_user
    current_app.login_manager._load_user()
  File "/hdd/code/eastbournecottage/venv/lib/python3.8/site-packages/flask_login/login_manager.py", line 318, in _load_user
    user = self._user_callback(user_id)
  File "/hdd/code/eastbournecottage/app/models.py", line 8, in load_user
    return User.query.get(int(id))
  File "/hdd/code/eastbournecottage/venv/lib/python3.8/site-packages/flask_sqlalchemy/__init__.py", line 512, in __get__
    mapper = orm.class_mapper(type)
  File "/hdd/code/eastbournecottage/venv/lib/python3.8/site-packages/sqlalchemy/orm/base.py", line 451, in class_mapper
    mapper = _inspect_mapped_class(class_, configure=configure)
  File "/hdd/code/eastbournecottage/venv/lib/python3.8/site-packages/sqlalchemy/orm/base.py", line 430, in _inspect_mapped_class
    mapper._configure_all()
  File "/hdd/code/eastbournecottage/venv/lib/python3.8/site-packages/sqlalchemy/orm/mapper.py", line 1354, in _configure_all
    configure_mappers()
  File "/hdd/code/eastbournecottage/venv/lib/python3.8/site-packages/sqlalchemy/orm/mapper.py", line 3280, in configure_mappers
    mapper._post_configure_properties()
  File "/hdd/code/eastbournecottage/venv/lib/python3.8/site-packages/sqlalchemy/orm/mapper.py", line 1967, in _post_configure_properties
    prop.init()
  File "/hdd/code/eastbournecottage/venv/lib/python3.8/site-packages/sqlalchemy/orm/interfaces.py", line 197, in init
    self.do_init()
  File "/hdd/code/eastbournecottage/venv/lib/python3.8/site-packages/sqlalchemy/orm/relationships.py", line 2080, in do_init
    self._generate_backref()
  File "/hdd/code/eastbournecottage/venv/lib/python3.8/site-packages/sqlalchemy/orm/relationships.py", line 2382, in _generate_backref
    mapper._configure_property(backref_key, relationship)
  File "/hdd/code/eastbournecottage/venv/lib/python3.8/site-packages/sqlalchemy/orm/mapper.py", line 1860, in _configure_property
    prop.init()
  File "/hdd/code/eastbournecottage/venv/lib/python3.8/site-packages/sqlalchemy/orm/interfaces.py", line 197, in init
    self.do_init()
  File "/hdd/code/eastbournecottage/venv/lib/python3.8/site-packages/sqlalchemy/orm/relationships.py", line 2080, in do_init
    self._generate_backref()
  File "/hdd/code/eastbournecottage/venv/lib/python3.8/site-packages/sqlalchemy/orm/relationships.py", line 2385, in _generate_backref
    self._add_reverse_property(self.back_populates)
  File "/hdd/code/eastbournecottage/venv/lib/python3.8/site-packages/sqlalchemy/orm/relationships.py", line 2027, in _add_reverse_property
    raise sa_exc.ArgumentError(
sqlalchemy.exc.ArgumentError: Billing.linked_payments and back-reference Billing.linked_invoice are both of the same direction symbol('ONETOMANY').  Did you mean to set remote_side on the many-to-one side ?
2021-04-12 17:05:50,573 INFO: eastbourne startup [in /hdd/code/eastbournecottage/app/__init__.py:29]
2021-04-12 17:05:50,656 INFO: eastbourne startup [in /hdd/code/eastbournecottage/app/__init__.py:29]
2021-04-12 17:05:50,658 INFO: eastbourne startup [in /hdd/code/eastbournecottage/app/__init__.py:29]
2021-04-12 17:05:50,724 INFO: eastbourne startup [in /hdd/code/eastbournecottage/app/__init__.py:29]
2021-04-12 17:05:56,372 ERROR: Exception on /get_billings [POST] [in /hdd/code/eastbournecottage/venv/lib/python3.8/site-packages/flask/app.py:1891]
Traceback (most recent call last):
  File "/hdd/code/eastbournecottage/venv/lib/python3.8/site-packages/flask/app.py", line 2447, in wsgi_app
    response = self.full_dispatch_request()
  File "/hdd/code/eastbournecottage/venv/lib/python3.8/site-packages/flask/app.py", line 1952, in full_dispatch_request
    rv = self.handle_user_exception(e)
  File "/hdd/code/eastbournecottage/venv/lib/python3.8/site-packages/flask/app.py", line 1821, in handle_user_exception
    reraise(exc_type, exc_value, tb)
  File "/hdd/code/eastbournecottage/venv/lib/python3.8/site-packages/flask/_compat.py", line 39, in reraise
    raise value
  File "/hdd/code/eastbournecottage/venv/lib/python3.8/site-packages/flask/app.py", line 1950, in full_dispatch_request
    rv = self.dispatch_request()
  File "/hdd/code/eastbournecottage/venv/lib/python3.8/site-packages/flask/app.py", line 1936, in dispatch_request
    return self.view_functions[rule.endpoint](**req.view_args)
  File "/hdd/code/eastbournecottage/venv/lib/python3.8/site-packages/flask_login/utils.py", line 272, in decorated_view
    return func(*args, **kwargs)
  File "/hdd/code/eastbournecottage/app/routes.py", line 509, in get_billings
    'linkedPayments': row.linked_payments.all(),
AttributeError: 'InstrumentedList' object has no attribute 'all'
2021-04-12 17:08:58,944 INFO: eastbourne startup [in /hdd/code/eastbournecottage/app/__init__.py:29]
2021-04-12 17:08:58,960 INFO: eastbourne startup [in /hdd/code/eastbournecottage/app/__init__.py:29]
2021-04-12 17:08:58,997 INFO: eastbourne startup [in /hdd/code/eastbournecottage/app/__init__.py:29]
2021-04-12 17:08:59,073 INFO: eastbourne startup [in /hdd/code/eastbournecottage/app/__init__.py:29]
2021-04-12 17:09:01,118 ERROR: Exception on /get_billings [POST] [in /hdd/code/eastbournecottage/venv/lib/python3.8/site-packages/flask/app.py:1891]
Traceback (most recent call last):
  File "/hdd/code/eastbournecottage/venv/lib/python3.8/site-packages/flask/app.py", line 2447, in wsgi_app
    response = self.full_dispatch_request()
  File "/hdd/code/eastbournecottage/venv/lib/python3.8/site-packages/flask/app.py", line 1952, in full_dispatch_request
    rv = self.handle_user_exception(e)
  File "/hdd/code/eastbournecottage/venv/lib/python3.8/site-packages/flask/app.py", line 1821, in handle_user_exception
    reraise(exc_type, exc_value, tb)
  File "/hdd/code/eastbournecottage/venv/lib/python3.8/site-packages/flask/_compat.py", line 39, in reraise
    raise value
  File "/hdd/code/eastbournecottage/venv/lib/python3.8/site-packages/flask/app.py", line 1950, in full_dispatch_request
    rv = self.dispatch_request()
  File "/hdd/code/eastbournecottage/venv/lib/python3.8/site-packages/flask/app.py", line 1936, in dispatch_request
    return self.view_functions[rule.endpoint](**req.view_args)
  File "/hdd/code/eastbournecottage/venv/lib/python3.8/site-packages/flask_login/utils.py", line 272, in decorated_view
    return func(*args, **kwargs)
  File "/hdd/code/eastbournecottage/app/routes.py", line 513, in get_billings
    'linkedPayments': linked_payments,
UnboundLocalError: local variable 'linked_payments' referenced before assignment
2021-04-12 17:10:13,056 INFO: eastbourne startup [in /hdd/code/eastbournecottage/app/__init__.py:29]
2021-04-12 17:10:13,141 INFO: eastbourne startup [in /hdd/code/eastbournecottage/app/__init__.py:29]
2021-04-12 17:10:13,203 INFO: eastbourne startup [in /hdd/code/eastbournecottage/app/__init__.py:29]
2021-04-12 17:10:13,268 INFO: eastbourne startup [in /hdd/code/eastbournecottage/app/__init__.py:29]
2021-04-12 17:10:15,074 ERROR: Exception on /get_billings [POST] [in /hdd/code/eastbournecottage/venv/lib/python3.8/site-packages/flask/app.py:1891]
Traceback (most recent call last):
  File "/hdd/code/eastbournecottage/venv/lib/python3.8/site-packages/flask/app.py", line 2447, in wsgi_app
    response = self.full_dispatch_request()
  File "/hdd/code/eastbournecottage/venv/lib/python3.8/site-packages/flask/app.py", line 1952, in full_dispatch_request
    rv = self.handle_user_exception(e)
  File "/hdd/code/eastbournecottage/venv/lib/python3.8/site-packages/flask/app.py", line 1821, in handle_user_exception
    reraise(exc_type, exc_value, tb)
  File "/hdd/code/eastbournecottage/venv/lib/python3.8/site-packages/flask/_compat.py", line 39, in reraise
    raise value
  File "/hdd/code/eastbournecottage/venv/lib/python3.8/site-packages/flask/app.py", line 1950, in full_dispatch_request
    rv = self.dispatch_request()
  File "/hdd/code/eastbournecottage/venv/lib/python3.8/site-packages/flask/app.py", line 1936, in dispatch_request
    return self.view_functions[rule.endpoint](**req.view_args)
  File "/hdd/code/eastbournecottage/venv/lib/python3.8/site-packages/flask_login/utils.py", line 272, in decorated_view
    return func(*args, **kwargs)
  File "/hdd/code/eastbournecottage/app/routes.py", line 483, in get_billings
    if (row.linked_payments.all()):
AttributeError: 'InstrumentedList' object has no attribute 'all'
