2021-05-10 20:13:20,537 ERROR: Exception on /set_billing_settings [POST] [in /hdd/code/eastbournecottage/venv/lib/python3.8/site-packages/flask/app.py:1891]
Traceback (most recent call last):
  File "/hdd/code/eastbournecottage/venv/lib/python3.8/site-packages/sqlalchemy/engine/base.py", line 1277, in _execute_context
    self.dialect.do_execute(
  File "/hdd/code/eastbournecottage/venv/lib/python3.8/site-packages/sqlalchemy/engine/default.py", line 593, in do_execute
    cursor.execute(statement, parameters)
  File "/hdd/code/eastbournecottage/venv/lib/python3.8/site-packages/pymysql/cursors.py", line 163, in execute
    result = self._query(query)
  File "/hdd/code/eastbournecottage/venv/lib/python3.8/site-packages/pymysql/cursors.py", line 321, in _query
    conn.query(q)
  File "/hdd/code/eastbournecottage/venv/lib/python3.8/site-packages/pymysql/connections.py", line 505, in query
    self._affected_rows = self._read_query_result(unbuffered=unbuffered)
  File "/hdd/code/eastbournecottage/venv/lib/python3.8/site-packages/pymysql/connections.py", line 724, in _read_query_result
    result.read()
  File "/hdd/code/eastbournecottage/venv/lib/python3.8/site-packages/pymysql/connections.py", line 1069, in read
    first_packet = self.connection._read_packet()
  File "/hdd/code/eastbournecottage/venv/lib/python3.8/site-packages/pymysql/connections.py", line 676, in _read_packet
    packet.raise_for_error()
  File "/hdd/code/eastbournecottage/venv/lib/python3.8/site-packages/pymysql/protocol.py", line 223, in raise_for_error
    err.raise_mysql_exception(self._data)
  File "/hdd/code/eastbournecottage/venv/lib/python3.8/site-packages/pymysql/err.py", line 107, in raise_mysql_exception
    raise errorclass(errno, errval)
pymysql.err.IntegrityError: (1062, "Duplicate entry '60' for key 'cancellation__breakpoint.cancel_by'")

The above exception was the direct cause of the following exception:

Traceback (most recent call last):
  File "/hdd/code/eastbournecottage/venv/lib/python3.8/site-packages/flask/app.py", line 2447, in wsgi_app
    response = self.full_dispatch_request()
  File "/hdd/code/eastbournecottage/venv/lib/python3.8/site-packages/flask/app.py", line 1952, in full_dispatch_request
    rv = self.handle_user_exception(e)
  File "/hdd/code/eastbournecottage/venv/lib/python3.8/site-packages/flask/app.py", line 1821, in handle_user_exception
    reraise(exc_type, exc_value, tb)
  File "/hdd/code/eastbournecottage/venv/lib/python3.8/site-packages/flask/_compat.py", line 39, in reraise
    raise value
  File "/hdd/code/eastbournecottage/venv/lib/python3.8/site-packages/flask/app.py", line 1950, in full_dispatch_request
    rv = self.dispatch_request()
  File "/hdd/code/eastbournecottage/venv/lib/python3.8/site-packages/flask/app.py", line 1936, in dispatch_request
    return self.view_functions[rule.endpoint](**req.view_args)
  File "/hdd/code/eastbournecottage/venv/lib/python3.8/site-packages/flask_login/utils.py", line 272, in decorated_view
    return func(*args, **kwargs)
  File "/hdd/code/eastbournecottage/app/routes.py", line 766, in set_billing_settings
    db_cancellation_breakpoints.filter(Cancellation_Breakpoint.id == row['id']).update({
  File "/hdd/code/eastbournecottage/venv/lib/python3.8/site-packages/sqlalchemy/orm/query.py", line 4031, in update
    update_op.exec_()
  File "/hdd/code/eastbournecottage/venv/lib/python3.8/site-packages/sqlalchemy/orm/persistence.py", line 1695, in exec_
    self._do_pre()
  File "<string>", line 1, in <lambda>
  File "/hdd/code/eastbournecottage/venv/lib/python3.8/site-packages/sqlalchemy/orm/persistence.py", line 1741, in _do_pre
    session._autoflush()
  File "/hdd/code/eastbournecottage/venv/lib/python3.8/site-packages/sqlalchemy/orm/session.py", line 1628, in _autoflush
    util.raise_(e, with_traceback=sys.exc_info()[2])
  File "/hdd/code/eastbournecottage/venv/lib/python3.8/site-packages/sqlalchemy/util/compat.py", line 178, in raise_
    raise exception
  File "/hdd/code/eastbournecottage/venv/lib/python3.8/site-packages/sqlalchemy/orm/session.py", line 1617, in _autoflush
    self.flush()
  File "/hdd/code/eastbournecottage/venv/lib/python3.8/site-packages/sqlalchemy/orm/session.py", line 2523, in flush
    self._flush(objects)
  File "/hdd/code/eastbournecottage/venv/lib/python3.8/site-packages/sqlalchemy/orm/session.py", line 2664, in _flush
    transaction.rollback(_capture_exception=True)
  File "/hdd/code/eastbournecottage/venv/lib/python3.8/site-packages/sqlalchemy/util/langhelpers.py", line 68, in __exit__
    compat.raise_(
  File "/hdd/code/eastbournecottage/venv/lib/python3.8/site-packages/sqlalchemy/util/compat.py", line 178, in raise_
    raise exception
  File "/hdd/code/eastbournecottage/venv/lib/python3.8/site-packages/sqlalchemy/orm/session.py", line 2624, in _flush
    flush_context.execute()
  File "/hdd/code/eastbournecottage/venv/lib/python3.8/site-packages/sqlalchemy/orm/unitofwork.py", line 422, in execute
    rec.execute(self)
  File "/hdd/code/eastbournecottage/venv/lib/python3.8/site-packages/sqlalchemy/orm/unitofwork.py", line 586, in execute
    persistence.save_obj(
  File "/hdd/code/eastbournecottage/venv/lib/python3.8/site-packages/sqlalchemy/orm/persistence.py", line 239, in save_obj
    _emit_insert_statements(
  File "/hdd/code/eastbournecottage/venv/lib/python3.8/site-packages/sqlalchemy/orm/persistence.py", line 1135, in _emit_insert_statements
    result = cached_connections[connection].execute(
  File "/hdd/code/eastbournecottage/venv/lib/python3.8/site-packages/sqlalchemy/engine/base.py", line 1014, in execute
    return meth(self, multiparams, params)
  File "/hdd/code/eastbournecottage/venv/lib/python3.8/site-packages/sqlalchemy/sql/elements.py", line 298, in _execute_on_connection
    return connection._execute_clauseelement(self, multiparams, params)
  File "/hdd/code/eastbournecottage/venv/lib/python3.8/site-packages/sqlalchemy/engine/base.py", line 1127, in _execute_clauseelement
    ret = self._execute_context(
  File "/hdd/code/eastbournecottage/venv/lib/python3.8/site-packages/sqlalchemy/engine/base.py", line 1317, in _execute_context
    self._handle_dbapi_exception(
  File "/hdd/code/eastbournecottage/venv/lib/python3.8/site-packages/sqlalchemy/engine/base.py", line 1511, in _handle_dbapi_exception
    util.raise_(
  File "/hdd/code/eastbournecottage/venv/lib/python3.8/site-packages/sqlalchemy/util/compat.py", line 178, in raise_
    raise exception
  File "/hdd/code/eastbournecottage/venv/lib/python3.8/site-packages/sqlalchemy/engine/base.py", line 1277, in _execute_context
    self.dialect.do_execute(
  File "/hdd/code/eastbournecottage/venv/lib/python3.8/site-packages/sqlalchemy/engine/default.py", line 593, in do_execute
    cursor.execute(statement, parameters)
  File "/hdd/code/eastbournecottage/venv/lib/python3.8/site-packages/pymysql/cursors.py", line 163, in execute
    result = self._query(query)
  File "/hdd/code/eastbournecottage/venv/lib/python3.8/site-packages/pymysql/cursors.py", line 321, in _query
    conn.query(q)
  File "/hdd/code/eastbournecottage/venv/lib/python3.8/site-packages/pymysql/connections.py", line 505, in query
    self._affected_rows = self._read_query_result(unbuffered=unbuffered)
  File "/hdd/code/eastbournecottage/venv/lib/python3.8/site-packages/pymysql/connections.py", line 724, in _read_query_result
    result.read()
  File "/hdd/code/eastbournecottage/venv/lib/python3.8/site-packages/pymysql/connections.py", line 1069, in read
    first_packet = self.connection._read_packet()
  File "/hdd/code/eastbournecottage/venv/lib/python3.8/site-packages/pymysql/connections.py", line 676, in _read_packet
    packet.raise_for_error()
  File "/hdd/code/eastbournecottage/venv/lib/python3.8/site-packages/pymysql/protocol.py", line 223, in raise_for_error
    err.raise_mysql_exception(self._data)
  File "/hdd/code/eastbournecottage/venv/lib/python3.8/site-packages/pymysql/err.py", line 107, in raise_mysql_exception
    raise errorclass(errno, errval)
sqlalchemy.exc.IntegrityError: (raised as a result of Query-invoked autoflush; consider using a session.no_autoflush block if this flush is occurring prematurely)
(pymysql.err.IntegrityError) (1062, "Duplicate entry '60' for key 'cancellation__breakpoint.cancel_by'")
[SQL: INSERT INTO cancellation__breakpoint (billing_settings_id, amount_refundable, cancel_by, check_in) VALUES (%(billing_settings_id)s, %(amount_refundable)s, %(cancel_by)s, %(check_in)s)]
[parameters: {'billing_settings_id': 1, 'amount_refundable': 100, 'cancel_by': 60, 'check_in': 0}]
(Background on this error at: http://sqlalche.me/e/13/gkpj)
2021-05-10 21:26:09,284 INFO: eastbourne startup [in /hdd/code/eastbournecottage/app/__init__.py:31]
2021-05-10 21:26:09,363 INFO: eastbourne startup [in /hdd/code/eastbournecottage/app/__init__.py:31]
2021-05-10 21:26:09,413 INFO: eastbourne startup [in /hdd/code/eastbournecottage/app/__init__.py:31]
2021-05-10 21:26:09,456 INFO: eastbourne startup [in /hdd/code/eastbournecottage/app/__init__.py:31]
2021-05-10 21:30:05,070 INFO: eastbourne startup [in /hdd/code/eastbournecottage/app/__init__.py:31]
2021-05-10 21:30:05,174 INFO: eastbourne startup [in /hdd/code/eastbournecottage/app/__init__.py:31]
2021-05-10 21:30:05,242 INFO: eastbourne startup [in /hdd/code/eastbournecottage/app/__init__.py:31]
2021-05-10 21:30:05,281 INFO: eastbourne startup [in /hdd/code/eastbournecottage/app/__init__.py:31]
2021-05-10 21:31:14,834 INFO: eastbourne startup [in /hdd/code/eastbournecottage/app/__init__.py:31]
2021-05-10 21:31:14,837 INFO: eastbourne startup [in /hdd/code/eastbournecottage/app/__init__.py:31]
2021-05-10 21:31:14,922 INFO: eastbourne startup [in /hdd/code/eastbournecottage/app/__init__.py:31]
2021-05-10 21:31:14,993 INFO: eastbourne startup [in /hdd/code/eastbournecottage/app/__init__.py:31]
2021-05-10 21:33:17,462 INFO: eastbourne startup [in /hdd/code/eastbournecottage/app/__init__.py:31]
2021-05-10 21:33:17,474 INFO: eastbourne startup [in /hdd/code/eastbournecottage/app/__init__.py:31]
2021-05-10 21:33:17,572 INFO: eastbourne startup [in /hdd/code/eastbournecottage/app/__init__.py:31]
