2021-03-28 16:00:24,542 ERROR: Exception on /admin [GET] [in /hdd/code/eastbournecottage/venv/lib/python3.8/site-packages/flask/app.py:1891]
Traceback (most recent call last):
  File "/hdd/code/eastbournecottage/venv/lib/python3.8/site-packages/flask/app.py", line 2447, in wsgi_app
    response = self.full_dispatch_request()
  File "/hdd/code/eastbournecottage/venv/lib/python3.8/site-packages/flask/app.py", line 1952, in full_dispatch_request
    rv = self.handle_user_exception(e)
  File "/hdd/code/eastbournecottage/venv/lib/python3.8/site-packages/flask/app.py", line 1821, in handle_user_exception
    reraise(exc_type, exc_value, tb)
  File "/hdd/code/eastbournecottage/venv/lib/python3.8/site-packages/flask/_compat.py", line 39, in reraise
    raise value
  File "/hdd/code/eastbournecottage/venv/lib/python3.8/site-packages/flask/app.py", line 1950, in full_dispatch_request
    rv = self.dispatch_request()
  File "/hdd/code/eastbournecottage/venv/lib/python3.8/site-packages/flask/app.py", line 1936, in dispatch_request
    return self.view_functions[rule.endpoint](**req.view_args)
  File "/hdd/code/eastbournecottage/venv/lib/python3.8/site-packages/flask_login/utils.py", line 270, in decorated_view
    elif not current_user.is_authenticated:
  File "/hdd/code/eastbournecottage/venv/lib/python3.8/site-packages/werkzeug/local.py", line 347, in __getattr__
    return getattr(self._get_current_object(), name)
  File "/hdd/code/eastbournecottage/venv/lib/python3.8/site-packages/werkzeug/local.py", line 306, in _get_current_object
    return self.__local()
  File "/hdd/code/eastbournecottage/venv/lib/python3.8/site-packages/flask_login/utils.py", line 26, in <lambda>
    current_user = LocalProxy(lambda: _get_user())
  File "/hdd/code/eastbournecottage/venv/lib/python3.8/site-packages/flask_login/utils.py", line 346, in _get_user
    current_app.login_manager._load_user()
  File "/hdd/code/eastbournecottage/venv/lib/python3.8/site-packages/flask_login/login_manager.py", line 318, in _load_user
    user = self._user_callback(user_id)
  File "/hdd/code/eastbournecottage/app/models.py", line 8, in load_user
    return User.query.get(int(id))
  File "/hdd/code/eastbournecottage/venv/lib/python3.8/site-packages/flask_sqlalchemy/__init__.py", line 512, in __get__
    mapper = orm.class_mapper(type)
  File "/hdd/code/eastbournecottage/venv/lib/python3.8/site-packages/sqlalchemy/orm/base.py", line 451, in class_mapper
    mapper = _inspect_mapped_class(class_, configure=configure)
  File "/hdd/code/eastbournecottage/venv/lib/python3.8/site-packages/sqlalchemy/orm/base.py", line 430, in _inspect_mapped_class
    mapper._configure_all()
  File "/hdd/code/eastbournecottage/venv/lib/python3.8/site-packages/sqlalchemy/orm/mapper.py", line 1354, in _configure_all
    configure_mappers()
  File "/hdd/code/eastbournecottage/venv/lib/python3.8/site-packages/sqlalchemy/orm/mapper.py", line 3280, in configure_mappers
    mapper._post_configure_properties()
  File "/hdd/code/eastbournecottage/venv/lib/python3.8/site-packages/sqlalchemy/orm/mapper.py", line 1967, in _post_configure_properties
    prop.init()
  File "/hdd/code/eastbournecottage/venv/lib/python3.8/site-packages/sqlalchemy/orm/interfaces.py", line 197, in init
    self.do_init()
  File "/hdd/code/eastbournecottage/venv/lib/python3.8/site-packages/sqlalchemy/orm/relationships.py", line 2080, in do_init
    self._generate_backref()
  File "/hdd/code/eastbournecottage/venv/lib/python3.8/site-packages/sqlalchemy/orm/relationships.py", line 2382, in _generate_backref
    mapper._configure_property(backref_key, relationship)
  File "/hdd/code/eastbournecottage/venv/lib/python3.8/site-packages/sqlalchemy/orm/mapper.py", line 1861, in _configure_property
    prop.post_instrument_class(self)
  File "/hdd/code/eastbournecottage/venv/lib/python3.8/site-packages/sqlalchemy/orm/interfaces.py", line 580, in post_instrument_class
    self.strategy.init_class_attribute(mapper)
  File "/hdd/code/eastbournecottage/venv/lib/python3.8/site-packages/sqlalchemy/orm/dynamic.py", line 35, in init_class_attribute
    raise exc.InvalidRequestError(
sqlalchemy.exc.InvalidRequestError: On relationship Payment_Breakpoint.billing_settings, 'dynamic' loaders cannot be used with many-to-one/one-to-one relationships and/or uselist=False.
2021-03-28 16:03:41,052 INFO: eastbourne startup [in /hdd/code/eastbournecottage/app/__init__.py:29]
2021-03-28 16:03:41,100 INFO: eastbourne startup [in /hdd/code/eastbournecottage/app/__init__.py:29]
2021-03-28 16:03:41,149 INFO: eastbourne startup [in /hdd/code/eastbournecottage/app/__init__.py:29]
2021-03-28 16:03:41,233 INFO: eastbourne startup [in /hdd/code/eastbournecottage/app/__init__.py:29]
2021-03-28 16:03:45,339 ERROR: Exception on /get_billing_settings [POST] [in /hdd/code/eastbournecottage/venv/lib/python3.8/site-packages/flask/app.py:1891]
Traceback (most recent call last):
  File "/hdd/code/eastbournecottage/venv/lib/python3.8/site-packages/flask/app.py", line 2447, in wsgi_app
    response = self.full_dispatch_request()
  File "/hdd/code/eastbournecottage/venv/lib/python3.8/site-packages/flask/app.py", line 1953, in full_dispatch_request
    return self.finalize_request(rv)
  File "/hdd/code/eastbournecottage/venv/lib/python3.8/site-packages/flask/app.py", line 1968, in finalize_request
    response = self.make_response(rv)
  File "/hdd/code/eastbournecottage/venv/lib/python3.8/site-packages/flask/app.py", line 2112, in make_response
    rv = jsonify(rv)
  File "/hdd/code/eastbournecottage/venv/lib/python3.8/site-packages/flask/json/__init__.py", line 370, in jsonify
    dumps(data, indent=indent, separators=separators) + "\n",
  File "/hdd/code/eastbournecottage/venv/lib/python3.8/site-packages/flask/json/__init__.py", line 211, in dumps
    rv = _json.dumps(obj, **kwargs)
  File "/home/anaconda3/lib/python3.8/json/__init__.py", line 234, in dumps
    return cls(
  File "/home/anaconda3/lib/python3.8/json/encoder.py", line 199, in encode
    chunks = self.iterencode(o, _one_shot=True)
  File "/home/anaconda3/lib/python3.8/json/encoder.py", line 257, in iterencode
    return _iterencode(o, 0)
  File "/hdd/code/eastbournecottage/venv/lib/python3.8/site-packages/flask/json/__init__.py", line 100, in default
    return _json.JSONEncoder.default(self, o)
  File "/home/anaconda3/lib/python3.8/json/encoder.py", line 179, in default
    raise TypeError(f'Object of type {o.__class__.__name__} '
TypeError: Object of type Payment_Breakpoint is not JSON serializable
2021-03-28 16:04:54,584 INFO: eastbourne startup [in /hdd/code/eastbournecottage/app/__init__.py:29]
2021-03-28 16:10:57,406 INFO: eastbourne startup [in /hdd/code/eastbournecottage/app/__init__.py:29]
2021-03-28 16:10:57,419 INFO: eastbourne startup [in /hdd/code/eastbournecottage/app/__init__.py:29]
2021-03-28 16:10:57,461 INFO: eastbourne startup [in /hdd/code/eastbournecottage/app/__init__.py:29]
2021-03-28 16:10:57,543 INFO: eastbourne startup [in /hdd/code/eastbournecottage/app/__init__.py:29]
2021-03-28 16:11:01,317 ERROR: Exception on /get_billing_settings [POST] [in /hdd/code/eastbournecottage/venv/lib/python3.8/site-packages/flask/app.py:1891]
Traceback (most recent call last):
  File "/hdd/code/eastbournecottage/venv/lib/python3.8/site-packages/flask/app.py", line 2447, in wsgi_app
    response = self.full_dispatch_request()
  File "/hdd/code/eastbournecottage/venv/lib/python3.8/site-packages/flask/app.py", line 1953, in full_dispatch_request
    return self.finalize_request(rv)
  File "/hdd/code/eastbournecottage/venv/lib/python3.8/site-packages/flask/app.py", line 1968, in finalize_request
    response = self.make_response(rv)
  File "/hdd/code/eastbournecottage/venv/lib/python3.8/site-packages/flask/app.py", line 2112, in make_response
    rv = jsonify(rv)
  File "/hdd/code/eastbournecottage/venv/lib/python3.8/site-packages/flask/json/__init__.py", line 370, in jsonify
    dumps(data, indent=indent, separators=separators) + "\n",
  File "/hdd/code/eastbournecottage/venv/lib/python3.8/site-packages/flask/json/__init__.py", line 211, in dumps
    rv = _json.dumps(obj, **kwargs)
  File "/home/anaconda3/lib/python3.8/json/__init__.py", line 234, in dumps
    return cls(
  File "/home/anaconda3/lib/python3.8/json/encoder.py", line 199, in encode
    chunks = self.iterencode(o, _one_shot=True)
  File "/home/anaconda3/lib/python3.8/json/encoder.py", line 257, in iterencode
    return _iterencode(o, 0)
  File "/hdd/code/eastbournecottage/venv/lib/python3.8/site-packages/flask/json/__init__.py", line 100, in default
    return _json.JSONEncoder.default(self, o)
  File "/home/anaconda3/lib/python3.8/json/encoder.py", line 179, in default
    raise TypeError(f'Object of type {o.__class__.__name__} '
TypeError: Object of type Payment_Breakpoint is not JSON serializable
2021-03-28 16:29:42,727 INFO: eastbourne startup [in /hdd/code/eastbournecottage/app/__init__.py:29]
2021-03-28 16:29:42,765 INFO: eastbourne startup [in /hdd/code/eastbournecottage/app/__init__.py:29]
2021-03-28 16:29:42,772 INFO: eastbourne startup [in /hdd/code/eastbournecottage/app/__init__.py:29]
2021-03-28 16:29:42,837 INFO: eastbourne startup [in /hdd/code/eastbournecottage/app/__init__.py:29]
